<?xml version="1.0"?>
<robot name="justina_right_arm" xmlns:xacro="http://www.ros.org/wiki/xacro">
  <xacro:include filename="$(find justina_description)/urdf/justina_right_arm.gazebo"/>
  
  <!--RIGHT ARM LINKS AND JOINTS-->
  <link name="shoulders_right_link">
    <visual>
      <origin xyz="0 0.01 0.02" rpy = "0 0 0"/>
      <geometry> 
        <box size = "0.04025 0.108 0.065"/> 
      </geometry>
      <material name = "ra_material_red"><color rgba="1.0 0 0 1"/></material>
    </visual>
    <collision>
      <origin xyz="0 0.01 0.02" rpy = "0 0 0"/>
      <geometry> 
        <box size = "0.04025 0.108 0.065"/> 
      </geometry>
    </collision>
    <inertial>
      <origin xyz="0 0.01 0.02" rpy = "0 0 0"/>
      <mass value="0.125"/>
      <inertia
        ixx="0.0015" ixy="0.0" ixz="0.0"
        iyy="0.002175" iyz="0.0"
        izz="0.003075"/>
    </inertial>
  </link>
  <link name="right_arm_link1">
    <visual>
      <origin xyz="0 0.01 -0.04881" rpy = "0 0 0"/>
      <geometry> 
        <box size = "0.04025 0.06 0.04025"/> 
      </geometry>
      <material name = "ra_material_orange"><color rgba="1.0 0.5 0 1"/></material>
    </visual>
    <collision>
      <origin xyz="0 0.01 -0.04881" rpy = "0 0 0"/>
      <geometry> 
        <box size = "0.04025 0.06 0.04025"/> 
      </geometry>
    </collision>
    <inertial>
      <origin xyz="0 0.01 -0.04881" rpy = "0 0 0"/>
      <mass value="0.125"/>
      <inertia
        ixx="0.0015" ixy="0.0" ixz="0.0"
        iyy="0.002175" iyz="0.0"
        izz="0.003075"/>
    </inertial>
  </link>
  <link name="right_arm_link2">
    <visual>
      <origin xyz="0 0 -0.125" rpy = "0 0 0"/>
      <geometry> 
        <box size = "0.04025 0.04025 0.19"/> 
      </geometry>
      <material name = "ra_material_yellow"><color rgba="1.0 1 0 1"/></material>
    </visual>
    <visual>
      <origin xyz="-0.01 0 -0.197" rpy = "0 0 0"/>
      <geometry> 
        <box size = "0.06 0.04025 0.04025"/> 
      </geometry>
      <material name = "la_material_yellow"><color rgba="1.0 1 0 1"/></material>
    </visual>
    <collision>
      <origin xyz="0 0 -0.125" rpy = "0 0 0"/>
      <geometry> 
        <box size = "0.04025 0.04025 0.19"/> 
      </geometry>
    </collision>
    <collision>
      <origin xyz="-0.01 0 -0.197" rpy = "0 0 0"/>
      <geometry> 
        <box size = "0.06 0.04025 0.04025"/> 
      </geometry>
    </collision>
    <inertial>
      <origin xyz="0 0 -0.175" rpy = "0 0 0"/>
      <mass value="0.155"/>
      <inertia
        ixx="0.0015" ixy="0.0" ixz="0.0"
        iyy="0.002175" iyz="0.0"
        izz="0.003075"/>
    </inertial>
  </link>
  <link name="right_arm_link3">
    <visual>
      <origin xyz="0 0 -0.04" rpy = "0 0 0"/>
      <geometry> 
        <box size = "0.04025 0.04025 0.05"/> 
      </geometry>
      <material name = "ra_material_green"><color rgba="0 0.5 0 1"/></material>
    </visual>
    <collision>
      <origin xyz="0 0 -0.04" rpy = "0 0 0"/>
      <geometry> 
        <box size = "0.04025 0.04025 0.05"/> 
      </geometry>
    </collision>
    <inertial>
      <origin xyz="0 0 -0.04" rpy = "0 0 0"/>
      <mass value="0.125"/>
      <inertia
        ixx="0.0015" ixy="0.0" ixz="0.0"
        iyy="0.002175" iyz="0.0"
        izz="0.003075"/>
    </inertial>
  </link>
  <link name="right_arm_link4">
    <visual>
      <origin xyz="0 0 -0.075" rpy = "0 0 0"/>
      <geometry> 
        <box size = "0.04025 0.04025 0.08"/> 
      </geometry>
      <material name = "ra_material_blue"><color rgba="0 0 1 1"/></material>
    </visual>
    <collision>
      <origin xyz="0 0 -0.075" rpy = "0 0 0"/>
      <geometry> 
        <box size = "0.04025 0.04025 0.08"/> 
      </geometry>
    </collision>
    <inertial>
      <origin xyz="0 0 -0.075" rpy = "0 0 0"/>
      <mass value="0.125"/>
      <inertia
        ixx="0.0015" ixy="0.0" ixz="0.0"
        iyy="0.002175" iyz="0.0"
        izz="0.003075"/>
    </inertial>
  </link>
  <link name="right_arm_link5">
    <visual>
      <origin xyz="0.02 0 0.005" rpy = "0 0 0"/>
      <geometry> 
        <box size = "0.07 0.03025 0.05"/> 
      </geometry>
      <material name = "ra_material_purple"><color rgba="1.0 0 1 1"/></material>
    </visual>
    <collision>
      <origin xyz="0.02 0 0.005" rpy = "0 0 0"/>
      <geometry> 
        <box size = "0.07 0.03025 0.05"/> 
      </geometry>
    </collision>
    <inertial>
      <origin xyz="0.02 0 0.005" rpy = "0 0 0"/>
      <mass value="0.125"/>
      <inertia
        ixx="0.0015" ixy="0.0" ixz="0.0"
        iyy="0.002175" iyz="0.0"
        izz="0.003075"/>
    </inertial>
  </link>
  <link name="right_arm_link6">
    <visual>
      <origin xyz="0.02 0 -0.045" rpy = "0 0 0"/>
      <geometry> 
        <box size = "0.07025 0.04025 0.02"/> 
      </geometry>
      <material name = "ra_material_red"><color rgba="1.0 0 0 1"/></material>
    </visual>
    <visual>
      <origin xyz="0 0 -0.088" rpy="0 0 0"/>
      <geometry>
        <box size = "0.03025 0.04025 0.03"/>
      </geometry>
      <material name ="ra_material_red"><color rgba= "1.0 0 0 1 "/></material>
    </visual>
    <collision>
      <origin xyz="0.02 0 -0.045" rpy = "0 0 0"/>
      <geometry> 
        <box size = "0.07025 0.04025 0.02"/> 
      </geometry>
    </collision>
    <collision>
      <origin xyz="0 0 -0.088" rpy="0 0 0"/>
      <geometry>
        <box size = "0.03025 0.04025 0.03"/>
      </geometry>
    </collision>
    <inertial>
      <origin xyz="0 0 -0.062" rpy = "0 0 0"/>
      <mass value="0.125"/>
      <inertia
        ixx="0.0015" ixy="0.0" ixz="0.0"
        iyy="0.002175" iyz="0.0"
        izz="0.003075"/>
    </inertial>
  </link>
  <link name="right_arm_link7">
    <visual>
      <origin xyz="0 0 -0.055" rpy = "0 0 0"/>
      <geometry> 
        <box size = "0.03 0.1 0.03"/> 
      </geometry>
      <material name = "ra_material_green"><color rgba="0 0.5 0 1"/></material>
    </visual>
    <collision>
      <origin xyz="0 0 -0.055" rpy = "0 0 0"/>
      <geometry> 
        <box size = "0.03 0.1 0.03"/> 
      </geometry>
    </collision>
    <inertial>
      <origin xyz="0 0 -0.055" rpy = "0 0 0"/>
      <mass value="0.125"/>
      <inertia
        ixx="0.0015" ixy="0.0" ixz="0.0"
        iyy="0.002175" iyz="0.0"
        izz="0.003075"/>
    </inertial>
  </link> 
  <link name="right_arm_grip_left">
    <visual>
      <origin xyz="0 0 -0.065" rpy = "0 0 0"/>
      <geometry> 
        <box size = "0.04 0.005 0.09"/> 
      </geometry>
      <material name = "ra_material"><color rgba="1.0 0.5 0 1"/></material>
    </visual>
    <collision>
      <origin xyz="0 0 -0.065" rpy = "0 0 0"/>
      <geometry> 
        <box size = "0.04 0.005 0.09"/> 
      </geometry>
    </collision>
    <inertial>
      <origin xyz="0 0 -0.065" rpy = "0 0 0"/>
      <mass value="0.125"/>
      <inertia
        ixx="0.0015" ixy="0.0" ixz="0.0"
        iyy="0.002175" iyz="0.0"
        izz="0.003075"/>
    </inertial>
  </link>
  <link name="right_arm_grip_right">
    <visual>
      <origin xyz="0 0 -0.065" rpy = "0 0 0"/>
      <geometry> 
        <box size = "0.04 0.005 0.09"/> 
      </geometry>
      <material name = "ra_material"><color rgba="1.0 0.5 0 1"/></material>
    </visual>
    <collision>
      <origin xyz="0 0 -0.065" rpy = "0 0 0"/>
      <geometry> 
        <box size = "0.04 0.005 0.09"/> 
      </geometry>
    </collision>
    <inertial>
      <origin xyz="0 0 -0.065" rpy = "0 0 0"/>
      <mass value="0.125"/>
      <inertia
        ixx="0.0015" ixy="0.0" ixz="0.0"
        iyy="0.002175" iyz="0.0"
        izz="0.003075"/>
    </inertial>
  </link>

  <link name="right_arm_grip_center"/>
  
  <joint name="ra_1_joint" type="revolute"> 
    <origin xyz="0 0.0 0" rpy="0 0 0"/>
    <parent link="shoulders_right_link"/>
    <child link="right_arm_link1"/>
    <axis xyz="0 -1 0" />
    <dynamics damping ="0.1" friction="0.01"/>
    <limit effort="16.0" velocity="3.0" lower="-1.7" upper="1.7"/>
  </joint>
  <joint name="ra_2_joint" type="revolute"> 
    <origin xyz="0 0.0 -0.06381" rpy="0 0 0"/>
    <parent link="right_arm_link1"/>
    <child link="right_arm_link2"/>
    <axis xyz="1 0 0" />
    <dynamics damping ="0.1" friction="0.01"/>
    <limit effort="8.0" velocity="3.0" lower="-1.85" upper="0.75"/>
  </joint>
  <joint name="ra_3_joint" type="revolute"> 
    <origin xyz="0 0.0 -0.215" rpy="0 0 0"/>
    <parent link="right_arm_link2"/>
    <child link="right_arm_link3"/>
    <axis xyz="0 0 1" />
    <dynamics damping ="0.1" friction="0.01"/>
    <limit effort="6.0" velocity="3.0" lower="-2.5" upper="2.5"/>
  </joint>
  <joint name="ra_4_joint" type="revolute"> 
    <origin xyz="0 0.0 -0.035" rpy="0 0 0"/>
    <parent link="right_arm_link3"/>
    <child link="right_arm_link4"/>
    <axis xyz="0 -1 0" />
    <dynamics damping ="0.1" friction="0.01"/>
    <limit effort="8.0" velocity="3.0" lower="-1.8" upper="1.8"/>
  </joint>
  <joint name="ra_5_joint" type="revolute"> 
    <origin xyz="0 0.0 -0.15" rpy="0 0 0"/>
    <parent link="right_arm_link4"/>
    <child link="right_arm_link5"/>
    <axis xyz="0 -1 0" />
    <dynamics damping ="0.1" friction="0.01"/>
    <limit effort="6.0" velocity="3.0" lower="-2.5" upper="2.5"/>
  </joint>
  <joint name="ra_6_joint" type="revolute"> 
    <origin xyz="0 0.0 0" rpy="0 0 0"/>
    <parent link="right_arm_link5"/>
    <child link="right_arm_link6"/>
    <axis xyz="1 0 0" />
    <dynamics damping ="0.1" friction="0.01"/>
    <limit effort="6.0" velocity="3.0" lower="-1.4" upper="1.57"/>
  </joint>
  <joint name="ra_7_joint" type="revolute"> 
    <origin xyz="0 0.0 -0.08" rpy="0 0 0"/>
    <parent link="right_arm_link6"/>
    <child link="right_arm_link7"/>
    <axis xyz="0 0 1" />
    <dynamics damping ="0.1" friction="0.01"/>
    <limit effort="3.0" velocity="3.0" lower="-2.5" upper="2.5"/>
  </joint>
  <joint name="ra_grip_left" type="revolute">
    <origin xyz="0 0.04 -0.06" rpy="0 0 0"/>
    <parent link="right_arm_link7"/> 
    <child link="right_arm_grip_left"/>
    <axis xyz="1 0 0" />
    <dynamics damping ="0.1" friction="0.01"/>
    <limit effort="3.0" velocity="3.0" lower="-0.3" upper="1.5"/>
  </joint>
  <joint name="ra_grip_right" type="revolute">
    <origin xyz="0 -0.04 -0.06" rpy="0 0 0"/>
    <parent link="right_arm_link7"/> 
    <child link="right_arm_grip_right"/>
    <axis xyz="-1 0 0" />
    <dynamics damping ="0.1" friction="0.01"/>
    <limit effort="3.0" velocity="3.0" lower="-0.3" upper="1.5"/>
  </joint>
  <joint name="ra_grip_center_joint" type="fixed">
    <origin xyz="0 0 -0.13" rpy="0 0 0"/>
    <parent link="right_arm_link7"/> 
    <child link="right_arm_grip_center"/> 
  </joint>
</robot>
