<?xml version="1.0"?>
<robot name="justina_base" xmlns:xacro="http://www.ros.org/wiki/xacro">
  <xacro:include filename="$(find justina_description)/urdf/justina_base.gazebo"/>
  
  <xacro:property name="base_width" value="0.42"/>
  <xacro:property name="base_depth" value="0.42"/>
  <xacro:property name="base_height" value="0.2"/>
  <xacro:property name="base_mass" value="30.0"/>
  <xacro:property name="wheel_radius" value="0.06"/>
  <xacro:property name="wheel_width" value="0.04"/>
  <xacro:property name="wheel_mass" value="30.0"/>
  <xacro:property name="PI_2" value="1.570796327"/>
  <xacro:property name="PI" value="3.14159265359"/>
  
  <!-- BASE LINKS AND JOINTS -->
  <link name="base_link">
    <visual>
      <origin xyz="0 0 0.235" rpy="0 0 0"/>
      <geometry> <box size="${base_width} ${base_depth} ${base_height}"/></geometry>
      <material name="blue"/>
    </visual>
    <collision>
      <origin xyz="0 0 0.235" rpy="0 0 0"/>
      <geometry> <box size="${base_width} ${base_depth} ${base_height}"/></geometry>
    </collision>
    <inertial>
      <origin xyz="0 0 0.235" rpy="0 0 0"/>
      <mass value="50.00"/>
      <xacro:box_inertia m="${base_mass}" x="${base_depth}" y="${base_width}" z="${base_height}"/>
    </inertial>
  </link>
  
  <joint name="wheel_left_connect" type="continuous">
    <origin xyz="0 0.24 0.065" rpy="-${PI_2} 0 0"/>
    <parent link="base_link"/>
    <child link="wheel_left"/>
    <axis xyz="0.0 0 1.0"/>
    <limit effort="11.067" velocity="20.8"/>
    <dynamics damping="1.0"/>
  </joint>
  
  <link name="wheel_left">
    <visual>
      <origin xyz="0 0 0" rpy="0 0 0"/>
      <geometry><cylinder length="${wheel_width}" radius="${wheel_radius}"/></geometry>
      <material name="gray"><color rgba="0 0 0 1" /></material>
    </visual>
    <collision>
      <origin xyz="0 0 0" rpy="0 0 0"/>
      <geometry><cylinder length="${wheel_width}" radius="${wheel_radius}"/></geometry>
    </collision>
    <inertial>
      <origin xyz="0 0 0"/>
      <mass value="0.2"/>
      <xacro:cylinder_inertia m="${wheel_mass}" r="${wheel_radius}" h="${wheel_width}"/>
    </inertial>
  </link>
    
  <joint name="wheel_right_connect" type="continuous">
    <origin xyz="0 -0.24 0.065" rpy="-1.5708 0 0"/>
    <parent link="base_link"/>
    <child link="wheel_right"/>
    <axis xyz="0.0 0 1.0"/>
    <limit effort="11.067" velocity="20.8"/>
    <dynamics damping="1.0"/>
  </joint>
  
  <link name="wheel_right">
    <visual>
      <origin xyz="0 0 0" rpy="0 0 0"/>
      <geometry><cylinder length="${wheel_width}" radius="${wheel_radius}"/></geometry>
      <material name="black"><color rgba="0 0 0 1" /></material>
    </visual>
    <collision>
      <origin xyz="0 0 0" rpy="0 0 0"/>
      <geometry><cylinder length="${wheel_width}" radius="${wheel_radius}"/></geometry>
    </collision>
    <inertial>
      <origin xyz="0 0 0" rpy="0 0 0"/>
      <mass value="0.2"/>
      <xacro:cylinder_inertia m="${wheel_mass}" r="${wheel_radius}" h="${wheel_width}"/>
    </inertial>
  </link>
  
  <joint name="wheel_back_connect_x" type="continuous">
    <origin xyz="-0.24 0 0.065" rpy="-1.5708 0 -1.5708"/>
    <parent link="base_link"/>
    <child link="wheel_back_x"/>
    <axis xyz="1 0 0"/>
    <limit effort="1.0" velocity="3.0"/>
    <dynamics damping="1.0"/>
  </joint>
  
  <link name="wheel_back_x">
    <inertial>
      <origin xyz="0 0 0" rpy="0 0 0"/>
      <mass value="0.2"/>
      <inertia ixx="0.015" ixy="0" ixz="0" iyy="0.015" iyz="0" izz="0.015"/>
    </inertial>
  </link>
  
  <joint name="wheel_back_connect_y" type="continuous">
    <axis xyz="0 1 0"/>
    <limit effort="8.85" velocity="10.0"/>
    <parent link="wheel_back_x"/>
    <child link="wheel_back_y"/>
  </joint>
  <link name="wheel_back_y">
    <inertial>
      <mass value="0.2"/>
      <origin xyz="0 0 0"/>
      <inertia ixx="0.015" ixy="0" ixz="0" iyy="0.015" iyz="0" izz="0.015"/>
    </inertial>
  </link>
  
  <joint name="wheel_back_connect_z" type="continuous">
    <axis xyz="0.0 0.0 1.0"/>
    <limit effort="8.85" velocity="10.0"/>
    <parent link="wheel_back_y"/>
    <child link="wheel_back_z"/>
  </joint>
  
  <link name="wheel_back_z">
    <visual>
      <geometry><sphere radius="0.06"/></geometry>
      <material name="wheel"/>
    </visual>
    <collision>
      <geometry><sphere radius="0.06"/></geometry>
    </collision>
    <inertial>
      <mass value="0.2"/>
      <origin xyz="0 0 0"/>
      <inertia ixx="0.015" ixy="0" ixz="0" iyy="0.015" iyz="0" izz="0.015"/>
    </inertial>
  </link>

  <joint name="wheel_front_connect_x" type="continuous">
    <origin xyz="0.24 0 0.065" rpy="-1.5708 0 -1.5708"/>
    <parent link="base_link"/>
    <child link="wheel_front_x"/>
    <axis xyz="1 0 0"/>
    <limit effort="1.0" velocity="3.0"/>
    <dynamics damping="1.0"/>
  </joint>
  
  <link name="wheel_front_x">
    <inertial>
      <mass value="0.2"/>
      <origin xyz="0 0 0"/>
      <inertia ixx="0.015" ixy="0" ixz="0" iyy="0.015" iyz="0" izz="0.015"/>
    </inertial>
  </link>
  
  <joint name="wheel_front_connect_y" type="continuous">
    <axis xyz="0.0 1.0 0.0"/>
    <limit effort="8.85" velocity="10.0"/>
    <parent link="wheel_front_x"/>
    <child link="wheel_front_y"/>
  </joint>
  
  <link name="wheel_front_y">
    <inertial>
      <mass value="0.2"/>
      <origin xyz="0 0 0"/>
      <inertia ixx="0.015" ixy="0" ixz="0" iyy="0.015" iyz="0" izz="0.015"/>
    </inertial>
  </link>
  
  <joint name="wheel_front_connect_z" type="continuous">
    <axis xyz="0.0 0.0 1.0"/>
    <limit effort="8.85" velocity="10.0"/>
    <parent link="wheel_front_y"/>
    <child link="wheel_front_z"/>
  </joint>
  
  <link name="wheel_front_z">
    <visual>
      <geometry><sphere radius="0.06"/></geometry>
      <material name="wheel"/>
    </visual>
    <collision>
      <geometry><sphere radius="0.06"/></geometry>
    </collision>
    <inertial>
      <mass value="0.2"/>
      <origin xyz="0 0 0"/>
      <inertia ixx="0.015" ixy="0" ixz="0" iyy="0.015" iyz="0" izz="0.015"/>
    </inertial>
  </link>

  <!-- LASER LINK AND JOINTS-->
  <link name="laser_link">
    <visual>
      <origin xyz="0 0 0" rpy="0 0 0"/>
      <geometry> <box size="0.08 0.08 0.1"/></geometry>
      <material name="black"/>
    </visual>
    <collision>
      <origin xyz="0 0 0" rpy="0 0 0"/>
      <geometry> <box size="0.08 0.08 0.1"/></geometry>
    </collision>
    <inertial>
      <origin xyz="0 0 0" rpy="0 0 0"/>
      <mass value="0.1"/>
      <xacro:box_inertia m="${0.05}" x="${0.08}" y="${0.08}" z="${0.1}"/>
    </inertial>
  </link>

  <link name="laser_link_rear">
    <visual>
      <origin xyz="0 0 0" rpy="0 0 0"/>
      <geometry> <box size="0.08 0.08 0.1"/></geometry>
      <material name="black"/>
    </visual>
    <collision>
      <origin xyz="0 0 0" rpy="0 0 0"/>
      <geometry> <box size="0.08 0.08 0.1"/></geometry>
    </collision>
    <inertial>
      <origin xyz="0 0 0" rpy="0 0 0"/>
      <mass value="0.1"/>
      <xacro:box_inertia m="${0.05}" x="${0.08}" y="${0.08}" z="${0.1}"/>
    </inertial>
  </link>
  
  <joint name="laser_connect" type="fixed">
    <origin xyz="0.17 0 0.44" />
    <parent link="base_link"/>
    <child link="laser_link"/>
  </joint>
  <joint name="rear_laser_connect" type="fixed">
    <origin xyz="-0.2 0 0.41" rpy="0 0 ${PI}"/>
    <parent link="base_link"/>
    <child link="laser_link_rear"/>
  </joint>
</robot>
  
