<?xml version="1.0"?>
<robot name="justina_torso" xmlns:xacro="http://www.ros.org/wiki/xacro">
  <xacro:include filename="$(find justina_description)/urdf/justina_torso.gazebo"/>
  
  <xacro:property name="torso_mass" value="0.6"/>
  <xacro:property name="spine_mass" value="0.1"/>
  <xacro:property name="PI_2" value="1.570796327"/>
  <xacro:property name="PI" value="3.14159265359"/>

  <link name="torso_link">
    <collision>
      <origin xyz= "0.04 -0.097 -0.55" rpy="1.5707 0 1.5707"/>
      <geometry>
	<mesh filename="package://justina_description/stl/torso.stl"/>
      </geometry>
    </collision>
    <visual>
      <origin xyz= "0.04 -0.097 -0.55" rpy="1.5707 0 1.5707"/>
      <geometry>
	<mesh filename="package://justina_description/stl/torso.stl"/>
      </geometry>
      <material name="black_gray"><color rgba="0.2 0.2 0.2 1"/></material>
    </visual>
    <inertial>
      <mass value="${torso_mass}"/>
      <origin xyz= "0.04 -0.097 -0.55" rpy="0 0 0"/>
      <xacro:box_inertia m="${torso_mass}" x="0.07" y="0.09" z="0.55"/>
    </inertial>
  </link>
  
  <joint name="spine_connect" type="prismatic"> 
    <origin xyz= "0.0 0 0.162" rpy="0 0 0"/>
    <parent link="torso_link"/>
    <child link="spine_link"/>
    <limit effort="1000" lower="0.0" upper="0.5" velocity="0.2"/>
    <dynamics damping ="0.1" />
    <axis xyz="0 0 1" />
  </joint>
  
  <link name="spine_link">
    <collision>
      <origin xyz= "0.0 0 -0.5325" rpy="0 0 1.5707"/>
      <geometry>
	<mesh filename="package://justina_description/stl/spine.stl"/>
      </geometry>
    </collision>
    <visual>
      <origin xyz= "0.0 0 -0.5325" rpy="0 0 1.5707"/>
      <geometry>
	<mesh filename="package://justina_description/stl/spine.stl"/>
      </geometry>
      <material name="gray_white"><color rgba="0.6 0.6 0.6 1"/></material>
    </visual>
    <inertial>
      <mass value="${spine_mass}"/>
      <origin xyz= "0 0 -0.5325" rpy="0 0 0"/>
      <xacro:box_inertia m="${spine_mass}" x="0.07" y="0.09" z="0.54"/>
    </inertial>
  </link>  
</robot>

