<?xml version="1.0"?>
<robot name="justina" xmlns:xacro="http://www.ros.org/wiki/xacro">
  <xacro:property name="base_radius" value="0.21"/>
  <xacro:property name="base_height" value="0.2"/>
  <xacro:property name="base_mass"   value="20.0"/>
  <xacro:property name="wheel_radius" value="0.08"/>
  <xacro:property name="wheel_width"  value="0.01"/>
  <xacro:property name="wheel_mass"   value="0.5"/>
  <xacro:property name="PI" value="3.14159265358979323846"/>
  
  <xacro:include filename="$(find justina_description)/urdf/macros.xacro"/>
  <xacro:include filename="$(find justina_description)/urdf/justina_base_omni.gazebo"/>

  <!-- MAIN BASE LINK -->
  <link name="base_link"/>
  <link name="base_center">
    <inertial>
      <origin xyz="0 0 0"/>
      <mass value="${base_mass}"/>
      <xacro:cylinder_inertia m="${base_mass}" r="${base_radius}" h="${base_height}"/>
    </inertial>
    <visual>
      <geometry><cylinder radius="${base_radius}" length="${base_height}"/></geometry>
      <material name="base_material"><color rgba="0 0 1 1"/></material>
    </visual>
    <collision>
      <geometry><cylinder radius="${base_radius}" length="${base_height}"/></geometry>
    </collision>
  </link>
  <link name="base_torso_support">
    <inertial>
      <origin xyz="0 0 0"/>
      <mass value="0.5"/>
      <xacro:box_inertia m="0.5" x="0.12" y="0.12" z="0.16"/>
    </inertial>
    <visual>
      <origin xyz="0 0 0" rpy="0 0 0"/>
      <geometry> <box size="0.12 0.12 0.16"/></geometry>
      <material name="black"/>
    </visual>
    <collision>
      <geometry> <box size="0.12 0.12 0.16"/></geometry>
    </collision>
  </link>
  <joint name="base_joint" type="fixed">
    <parent link="base_link" />
    <child link="base_center" />
    <origin xyz="0 0 0.13"/>
  </joint>
  <joint name="base_torso_support_joint" type="fixed">
    <parent link="base_center" />
    <child link="base_torso_support" />
    <origin xyz="0 0 0.18"/>
  </joint>

  <!-- LEFT WHEEL ACTUATOR-->
  <link name="left_wheel_link">
    <inertial>
      <origin xyz="0 0 0"/>
      <mass value="${wheel_mass}"/>
      <xacro:cylinder_inertia m="${wheel_mass}" r="${wheel_radius}" h="${wheel_width}"/>
    </inertial>
    <visual>
      <geometry><cylinder radius="${wheel_radius}" length="${wheel_width}"/></geometry>
      <material name="wheel_material"><color rgba="0 0 0 1"/></material>
    </visual>
    <collision>
      <geometry><cylinder radius="${wheel_radius}" length="${wheel_width}"/></geometry>
    </collision>
  </link>
  <joint name="wheel_left_joint" type="continuous">
    <parent link="base_center" />
    <child link="left_wheel_link" />
    <axis xyz="0 0 1"/>
    <origin xyz="${(base_radius+0.03)*cos( PI/3)} ${(base_radius+0.03)*sin( PI/3)} -0.05" rpy="${PI/2} 0 ${ PI/3+PI/2}"/>
    <limit velocity="30.0" effort="5.0"/>
    <dynamics damping="0.5" friction="0.01"/>
  </joint>  
  
  <!-- RIGHT WHEEL ACTUATOR-->
  <link name="right_wheel_link">
    <inertial>
      <origin xyz="0 0 0"/>
      <mass value="${wheel_mass}"/>
      <xacro:cylinder_inertia m="${wheel_mass}" r="${wheel_radius}" h="${wheel_width}"/>
    </inertial>
    <visual>
      <geometry><cylinder radius="${wheel_radius}" length="${wheel_width}"/></geometry>
      <material name="wheel_material"><color rgba="0 0 0 1"/></material>
    </visual>
    <collision>
      <geometry><cylinder radius="${wheel_radius}" length="${wheel_width}"/></geometry>
    </collision>
  </link>
  <joint name="wheel_right_joint" type="continuous">
    <parent link="base_center" />
    <child link="right_wheel_link" />
    <axis xyz="0 0 1"/>
    <origin xyz="${(base_radius+0.03)*cos(-PI/3)} ${(base_radius+0.03)*sin(-PI/3)} -0.05" rpy="${PI/2} 0 ${-PI/3+PI/2}"/>
    <limit velocity="30.0" effort="5.0"/>
    <dynamics damping="0.5" friction="0.01"/>
  </joint>

  <!-- BACK WHEEL ACTUATOR-->
  <link name="back_wheel_link">
    <inertial>
      <origin xyz="0 0 0"/>
      <mass value="${wheel_mass}"/>
      <xacro:cylinder_inertia m="${wheel_mass}" r="${wheel_radius}" h="${wheel_width}"/>
    </inertial>
    <visual>
      <geometry><cylinder radius="${wheel_radius}" length="${wheel_width}"/></geometry>
      <material name="wheel_material"><color rgba="0 0 0 1"/></material>
    </visual>
    <collision>
      <geometry><cylinder radius="${wheel_radius}" length="${wheel_width}"/></geometry>
    </collision>
  </link>
  <joint name="wheel_back_joint" type="continuous">
    <parent link="base_center" />
    <child link="back_wheel_link" />
    <axis xyz="0 0 1"/>
    <origin xyz="${(base_radius+0.03)*cos(PI)} ${(base_radius+0.03)*sin(PI)} -0.05" rpy="${PI/2} 0 ${PI+PI/2}"/>
    <limit velocity="30.0" effort="5.0"/>
    <dynamics damping="0.5" friction="0.01"/>
  </joint>

  <!-- LASER LINK AND JOINTS-->
  <link name="laser_link">
    <visual>
      <origin xyz="0 0 0" rpy="0 0 0"/>
      <geometry> <box size="0.05 0.05 0.08"/></geometry>
      <material name="black"/>
    </visual>
    <collision>
      <origin xyz="0 0 0" rpy="0 0 0"/>
      <geometry> <box size="0.05 0.05 0.08"/></geometry>
    </collision>
    <inertial>
      <origin xyz="0 0 0" rpy="0 0 0"/>
      <mass value="0.1"/>
      <xacro:box_inertia m="${0.1}" x="${0.05}" y="${0.05}" z="${0.08}"/>
    </inertial>
  </link>
  <link name="laser_link_rear">
    <visual>
      <origin xyz="0 0 0" rpy="0 0 0"/>
      <geometry> <box size="0.05 0.05 0.08"/></geometry>
      <material name="black"/>
    </visual>
    <collision>
      <origin xyz="0 0 0" rpy="0 0 0"/>
      <geometry> <box size="0.05 0.05 0.08"/></geometry>
    </collision>
    <inertial>
      <origin xyz="0 0 0" rpy="0 0 0"/>
      <mass value="0.1"/>
      <xacro:box_inertia m="${0.1}" x="${0.05}" y="${0.05}" z="${0.08}"/>
    </inertial>
  </link>
  <joint name="laser_connect" type="fixed">
    <origin xyz="0.17 0 0.14" />
    <parent link="base_center"/>
    <child link="laser_link"/>
  </joint>
  <joint name="rear_laser_connect" type="fixed">
    <origin xyz="-0.2 0 0.14" rpy="0 0 ${PI}"/>
    <parent link="base_center"/>
    <child link="laser_link_rear"/>
  </joint>
</robot>
