<?xml version="1.0" ?>
<sdf version="1.4">
    <model name='openable_hinged_door_z_reversely'>
      <joint name="frame_to_world_joint" type="revolute">
          <parent>world</parent>
          <child>frame</child>
          <!-- Mimic fixed joint  -->
          <pose>0 -0.45 0 0 0 0</pose>
          <axis>
              <xyz>0 0 1</xyz>
              <limit>
                  <lower>0</lower>
                  <upper>0</upper>
              </limit>
          </axis>
      </joint>
      <link name='frame'>
        <pose>0 0.45 0 0 0 0</pose>
        <visual name='left_frame'>
          <pose>0 -0.4325 1.025 0 0 0</pose>
          <geometry>
            <box>
              <size>0.055 0.035 2.050</size>
            </box>
          </geometry>
          <material>
            <script>
              <uri>model://base_materials/color/scripts</uri>
              <name>hsr_color/white</name>
            </script>
          </material>
        </visual>
        <collision name='collision_left_frame'>
          <pose>0 -0.4325 1.025 0 0 0</pose>
          <geometry>
            <box>
              <size>0.055 0.035 2.050</size>
            </box>
          </geometry>
          <max_contacts>10</max_contacts>
          <surface>
            <bounce/>
            <friction>
              <ode/>
            </friction>
            <contact>
              <ode/>
            </contact>
          </surface>
        </collision>
        <visual name='top_frame'>
          <pose>0 0 2.070 0 0 0</pose>
          <geometry>
            <box>
              <size>0.055 0.9 0.04</size>
            </box>
          </geometry>
          <material>
            <script>
              <uri>model://base_materials/color/scripts</uri>
              <name>hsr_color/white</name>
            </script>
          </material>
        </visual>
        <collision name='collision_top_frame'>
          <pose>0 0 2.070 0 0 0</pose>
          <geometry>
            <box>
              <size>0.055 0.9 0.04</size>
            </box>
          </geometry>
          <max_contacts>10</max_contacts>
          <surface>
            <bounce/>
            <friction>
              <ode/>
            </friction>
            <contact>
              <ode/>
            </contact>
          </surface>
        </collision>
        <velocity_decay>
          <linear>0</linear>
          <angular>0</angular>
        </velocity_decay>
        <self_collide>0</self_collide>
        <kinematic>0</kinematic>
        <gravity>1</gravity>
      </link>
      <link name='door'>
        <pose>0 0 0 0 0 0</pose>
        <inertial>
          <mass>50</mass>
          <inertia>
            <ixx>14.2</ixx>
            <ixy>0</ixy>
            <ixz>0</ixz>
            <iyy>17.2</iyy>
            <iyz>0</iyz>
            <izz>3.0</izz>
          </inertia>
        </inertial>
        <visual name='door'>
          <pose>0 0.45 1.050 0 0 0</pose>
          <geometry>
            <box>
              <size>0.055 0.830 2.0</size>
            </box>
          </geometry>
          <material>
            <script>
              <uri>model://base_materials/wood/scripts/wood.material</uri>
              <name>base_materials/wood</name>
            </script>
          </material>
        </visual>
        <collision name='collision_door'>
          <pose>0 0.45 1.050 0 0 0</pose>
          <geometry>
            <box>
              <size>0.055 0.830 2.0</size>
            </box>
          </geometry>
          <max_contacts>10</max_contacts>
          <surface>
            <bounce/>
            <friction>
              <ode/>
            </friction>
            <contact>
              <ode/>
            </contact>
          </surface>
        </collision>
        <visual name='handle_lock1'>
          <pose>0 0.785 1.03 0 0 0</pose>
          <geometry>
            <box>
              <size>0.075 0.005 0.04</size>
            </box>
          </geometry>
          <material>
            <script>
              <uri>model://base_materials/color/scripts</uri>
              <name>hsr_color/white</name>
            </script>
          </material>
        </visual>
        <visual name='handle_lock2'>
          <pose>0 0.785 1.03 0 1.5708 0</pose>
          <geometry>
            <cylinder>
              <radius>0.025</radius>
              <length>0.065</length>
            </cylinder>
          </geometry>
          <material>
            <script>
              <uri>model://base_materials/color/scripts</uri>
              <name>hsr_color/white</name>
            </script>
          </material>
        </visual>
        <velocity_decay>
          <linear>0</linear>
          <angular>0</angular>
        </velocity_decay>
        <self_collide>0</self_collide>
        <kinematic>0</kinematic>
        <gravity>1</gravity>
      </link>
      <link name='handles'>
        <pose>0.0 0.8 0.93 0 3.14 1.57</pose>
        <visual name="handle1_visual">
          <pose>0.015 0 0 -1.57 0 0</pose>
          <geometry>
            <mesh>
              <uri>model://openable_hinged_door_z_normally/meshes/door_handle_small.dae</uri>
            </mesh>
          </geometry>
        </visual>
        <collision name="handle1_collision">
          <pose>0.015 0 0 -1.57 0 0</pose>
          <geometry>
            <mesh>
              <uri>model://openable_hinged_door_z_normally/meshes/door_handle_small.dae</uri>
            </mesh>
          </geometry>
        </collision>
      </link>
      <joint name="handle" type="revolute">
        <parent>door</parent>
        <child>handles</child>
        <pose>0.013 0 0 0 0 0</pose>
        <axis>
          <xyz>1 0 0</xyz>
          <limit>
            <lower>0</lower>
            <upper>0.52</upper>
          </limit>
          <dynamics>
            <damping>0.1</damping>
            <spring_stiffness>0.3</spring_stiffness>
          </dynamics>
        </axis>
        <physics>
          <ode>
            <cfm_damping>1</cfm_damping>
          </ode>
        </physics>
      </joint>
      <joint name="hinge" type="revolute">
        <parent>frame</parent>
        <child>door</child>
        <axis>
          <xyz>0 0 1</xyz>
          <limit>
            <lower>-1.58</lower>
            <upper>0</upper>
            <effort></effort>
            <velocity></velocity>
          </limit>
          <dynamics>
            <damping>1.0</damping>
            <friction>1.0</friction>
          </dynamics>
        </axis>
        <physics>
          <ode>
            <cfm_damping>1</cfm_damping>
          </ode>
        </physics>
      </joint>
      <static>0</static>
    </model>
</sdf>
